test/AAPLOrders.txt
SELL GFD 1 220.1 100 1
SELL GFD 1 215.1 100 2 
SELL GFD 1 217.07 500 3 
SELL GFD 1 214.07 500 4 
BUY GFD 1 213.99 100 5
BUY GFD 1 213.59 500 6
BUY GFD 1 214.07 50 7
BUY GFD 1 214.0 60 8
BUY GFD 1 214.05 70 9
SELL GFD 1 214.08 150 10
MODIFY 1 8 SELL 214.06 150
SELL GFD 1 214.12 100 11
BUY IOC 1 214.2 100 12
BUY IOC 1 214.09 100 13
BUY IOC 1 214.21 1000 14
SELL GFD 1 214.13 150 15
SELL GFD 1 214.15 250 16
SELL GFD 1 214.11 500 17
BUY IOC 1 214.16 1000 18
BUY GFD 1 213.97 100 19
BUY IOC 1 214.16 1000 20
BUY IOC 1 214.06 1000 21
