test/MSFTOrders.txt
SELL GFD 3 430.1 100 1
SELL GFD 3 429.1 100 2 
SELL GFD 3 428.07 500 3 
SELL GFD 3 427.87 500 4 
BUY GFD 3 423.99 100 5
BUY GFD 3 423.59 500 6
BUY GFD 3 427.07 50 7
BUY GFD 3 427.0 60 8
BUY GFD 3 427.05 70 9
SELL GFD 3 427.08 150 10
MODIFY 3 10 SELL 427.04 150
SELL GFD 3 426.12 100 11
BUY IOC 3 425.2 100 12
BUY IOC 3 425.09 100 13
BUY IOC 3 425.21 1000 14
SELL GFD 3 425.13 150 15
SELL GFD 3 425.15 250 16
SELL GFD 3 425.11 500 17
BUY IOC 3 425.16 1000 18
BUY GFD 3 425.97 100 19
BUY IOC 3 425.16 1000 20
BUY IOC 3 425.06 1000 21
