test/NVDAOrders.txt
SELL GFD 2 120.1 100 1
SELL GFD 2 115.1 100 2 
SELL GFD 2 117.07 500 3 
SELL GFD 2 114.07 500 3 
BUY GFD 2 113.99 100 4
BUY GFD 2 113.59 500 4
BUY GFD 2 114.07 50 5
BUY GFD 2 114.0 60 6
BUY GFD 2 114.05 70 7
SELL GFD 2 114.08 150 8
MODIFY 2 8 SELL 114.06 150
SELL GFD 2 114.12 100 9
BUY IOC 2 114.2 100 10
BUY IOC 2 114.09 100 11
BUY IOC 2 114.21 1000 12
SELL GFD 2 114.13 150 12
SELL GFD 2 114.15 250 13
SELL GFD 2 114.11 500 14
BUY IOC 2 114.16 1000 15
BUY GFD 2 113.97 100 16
BUY IOC 2 114.16 1000 17
BUY IOC 2 114.06 1000 18
