test/TestData.txt
SELL GFD 1100 100 order1
SELL GFD 1200 100 order2
SELL GFD 1000 50 order3
PRINT
BUY GFD 1000 100 order4
BUY GFD 1050 50 order5
BUY GFD 1075 60 order6
BUY GFD 1025 70 order7
PRINT
SELL GFD 1070 100 order8
MODIFY order6 SELL 1065 150 order9
PRINT
SELL GFD 1040 100 order10
BUY IOC 1000 100 order11
PRINT
BUY IOC 1070 100 order12
PRINT
