test/TestData2.txt
SELL GFD 1 220.1 100 1
SELL GFD 1 215.1 100 2 
SELL GFD 1 217.07 500 3 
SELL GFD 1 214.07 500 3 
BUY GFD 1 213.99 100 4
BUY GFD 1 213.59 500 4
CANCEL 1 4
BUY GFD 1 214.07 50 5
BUY GFD 1 214.0 60 6
BUY GFD 1 214.05 70 7
CANCEL 1 7
SELL GFD 1 214.08 150 8
MODIFY 1 8 SELL 214.06 150
SELL GFD 1 214.12 100 9
BUY IOC 1 214.2 100 10
BUY IOC 1 214.09 100 11
BUY IOC 1 214.21 1000 12
CANCEL 1 10
SELL GFD 1 214.13 150 12
SELL GFD 1 214.15 250 13
SELL GFD 1 214.11 500 14
BUY IOC 1 214.16 1000 15
BUY GFD 1 213.97 100 16
BUY IOC 1 214.16 1000 17
BUY IOC 1 214.06 1000 18
